<?xml version="1.0"?>

<robot name="dogebot">

  <!-- *************************************************** -->
  <!-- ******************* RVIZ Colors ******************* -->
  <!-- *************************************************** -->

  <material name="white">    <color rgba="1.00 1.00 1.00 1"/>  </material>
  <material name="gray">     <color rgba="0.60 0.60 0.60 1"/>  </material>
  <material name="table">    <color rgba="0.85 0.77 0.77 1"/>  </material>
  <material name="black">    <color rgba="0.00 0.00 0.00 1"/>  </material>

  <material name="red">      <color rgba="1.00 0.00 0.00 1"/>  </material>
  <material name="green">    <color rgba="0.00 1.00 0.00 1"/>  </material>
  <material name="blue">     <color rgba="0.00 0.00 1.00 1"/>  </material>

  <material name="cyan">     <color rgba="0.00 1.00 1.00 1"/>  </material>
  <material name="magenta">  <color rgba="1.00 0.00 1.00 1"/>  </material>
  <material name="yellow">   <color rgba="1.00 1.00 0.00 1"/>  </material>

  <material name="orange">   <color rgba="1.00 0.65 0.00 1"/>  </material>

  
  <!-- *************************************************** -->
  <!-- ******************** Kinematics ******************* -->
  <!-- *************************************************** -->
  <!-- Note the 'origin' tag in the joints defines the shift and
       reorientation, i.e. the transform.  For moving joints, this
       happens before the continuous joint rotates around 'axis'. -->

<!-- ******************** World and Body ******************* -->
      <link name="world"> 
      </link>
      
      <joint name="world_to_body" type="fixed">
        <parent link="world"/>
        <child  link="body"/>
        <origin xyz="0 0 1" rpy="0 0 0"/>
      </joint>

      <link name="body"> 
        <visual>
            <geometry>
                <box size= "2 1 0.1"/>
            </geometry>
            <origin xyz="0 0 0" rpy="0 0 0"/>
            <material name="gray"/>
        </visual>
      </link>

    <xacro:macro name="leg" params="x y legname">
    <!-- *** Translation: body to hip joint *** -->
      <joint name="body_${legname}" type="fixed">
        <parent link="body"/>
        <child  link="body_leg_${legname}_link"/>
        <origin xyz="${x} ${y} 0" rpy="0 0 0"/>
      </joint>

      <link name="body_leg_${legname}_link">
      </link>

    <!-- *** Rotation about z: hip joint *** -->
      <joint name="hip_${legname}_z" type="continuous">
        <parent link="body_leg_${legname}_link"/>
        <child  link="hip_${legname}_link"/>
        <origin xyz="0 0 0" rpy="-1.5708 0 0"/>
        <axis   xyz="0 0 1"/>
      </joint>

      <link name="hip_${legname}_link">
        <visual>
            <geometry>
                <sphere radius="0.1"/>
            </geometry>
            <material name="blue"/>
        </visual>
      </link>
      
    <!-- *** Rotation about x: hip joint *** -->
      <joint name="hip_${legname}_x" type="continuous">
        <parent link="hip_${legname}_link"/>
        <child  link="thigh_${legname}"/>
        <origin xyz="0 0 0" rpy="0 0 0.7854"/>
        <axis   xyz="1 0 0"/>
      </joint>

      <link name="thigh_${legname}">
        <visual>
            <geometry>
                <cylinder length="0.7" radius="0.02"/>
            </geometry>
            <origin xyz="0 0.35 0" rpy="1.5708 0 0"/>
            <material name="white"/>
        </visual>
      </link>

    <!-- *** Translation: hip to knee joint *** -->
      <joint name="thighlink_${legname}" type="fixed">
        <parent link="thigh_${legname}"/>
        <child  link="thighlink_${legname}"/>
        <origin xyz="0 0.7 0" rpy="0 0 0"/>
      </joint>

      <link name="thighlink_${legname}">
        <visual>
            <geometry>
                <cylinder length="0.2" radius="0.05"/>
            </geometry>
            <material name="black"/>
        </visual>   
      </link>

    <!-- *** Rotation: knee joint *** -->
      <joint name="knee_${legname}" type="continuous">
        <parent link="thighlink_${legname}"/>
        <child  link="calf_${legname}"/>
        <origin xyz="0 0 0" rpy="0 0 0"/>
        <axis   xyz="0 0 1"/>
      </joint>

      <link name="calf_${legname}">
        <visual>
            <geometry>
                <cylinder length="0.7" radius="0.02"/>
            </geometry>
            <origin xyz="0.35 0 0" rpy="0 1.5708 0"/>
            <material name="green"/>
        </visual>
      </link>

    <!-- *** Translation: knee to calf joint *** -->
      <joint name="calflink_${legname}" type="fixed">
        <parent link="calf_${legname}"/>
        <child  link="tip_${legname}"/>
        <origin xyz="0.7 0 0" rpy="0 0 0"/>
      </joint>
      
      <link name="tip_${legname}">
        <visual>
            <geometry>
                <sphere radius="0.05"/>
            </geometry>
            <material name="magenta"/>
        </visual>
      </link>
    </xacro:macro>

    <!-- ******************** Leg Xacro Chains ******************* -->  
    <xacro:leg x="1" y="0.5" legname="1" />  
    <xacro:leg x="1" y="-0.5" legname="2" />  
    <xacro:leg x="-1" y="0.5" legname="3" />  
    <xacro:leg x="-1" y="-0.5" legname="4" />  
  
</robot>
